Candidate: CVE-2022-36087
PublicDate: 2022-09-09 21:15:00 UTC
References:
 https://cve.mitre.org/cgi-bin/cvename.cgi?name=CVE-2022-36087
 https://github.com/oauthlib/oauthlib/security/advisories/GHSA-3pgj-pg6c-r5p7
 https://github.com/oauthlib/oauthlib/blob/2b8a44855a51ad5a5b0c348a08c2564a2e197ea2/oauthlib/uri_validate.py
 https://github.com/oauthlib/oauthlib/releases/tag/v3.2.1
 https://github.com/oauthlib/oauthlib/blob/d4bafd9f1d0eba3766e933b1ac598cbbf37b8914/oauthlib/oauth2/rfc6749/grant_types/base.py#L232
 https://github.com/oauthlib/oauthlib/commit/2e40b412c844ecc4673c3fa3f72181f228bdbacd
Description:
 OAuthLib is an implementation of the OAuth request-signing logic for Python
 3.6+. In OAuthLib versions 3.1.1 until 3.2.1, an attacker providing
 malicious redirect uri can cause denial of service. An attacker can also
 leverage usage of `uri_validate` functions depending where it is used.
 OAuthLib applications using OAuth2.0 provider support or use directly
 `uri_validate` are affected by this issue. Version 3.2.1 contains a patch.
 There are no known workarounds.
Ubuntu-Description:
Notes:
Mitigation:
Bugs:
Priority: medium
Discovered-by:
Assigned-to:
CVSS:

Patches_python-oauthlib:
upstream_python-oauthlib: needs-triage
esm-infra/xenial_python-oauthlib: needs-triage
trusty_python-oauthlib: ignored (out of standard support)
xenial_python-oauthlib: ignored (out of standard support)
bionic_python-oauthlib: needs-triage
focal_python-oauthlib: needs-triage
jammy_python-oauthlib: needs-triage
vivid/stable-phone-overlay_python-oauthlib: needs-triage
vivid/ubuntu-core_python-oauthlib: needs-triage
devel_python-oauthlib: needs-triage
